Workbook

Sheet NEW
A1: 날짜 | B1: 증권사 | C1: 상품명 | D1: 코드 | E1: 종목 | F1: 비중 | K1: 변동폭 | L1: 투자 판단 | M1: 사유
A2: 46002 | B2: 삼성 | C2: 트루밸류 | D2: =_xlfn.XLOOKUP(E2,Code!A:A,Code!B:B) | E2: 삼성전자 | F2: 30 | G2: =B2&E2 | H2: =A2&B2&E2
A3: 46002 | B3: 삼성 | C3: 트루밸류 | D3: =_xlfn.XLOOKUP(E3,Code!A:A,Code!B:B) | E3: SK하이닉스 | F3: 15 | G3: =B3&E3 | H3: =A3&B3&E3
A4: 46002 | B4: 삼성 | C4: 트루밸류 | D4: =_xlfn.XLOOKUP(E4,Code!A:A,Code!B:B) | E4: 하이브 | F4: 12 | G4: =B4&E4 | H4: =A4&B4&E4
A5: 46002 | B5: 삼성 | C5: 트루밸류 | D5: =_xlfn.XLOOKUP(E5,Code!A:A,Code!B:B) | E5: 두산에너빌리티 | F5: 10 | G5: =B5&E5 | H5: =A5&B5&E5
A6: 46002 | B6: 삼성 | C6: 트루밸류 | D6: =_xlfn.XLOOKUP(E6,Code!A:A,Code!B:B) | E6: 알테오젠 | F6: 7 | G6: =B6&E6 | H6: =A6&B6&E6
A7: 46002 | B7: 삼성 | C7: 트루밸류 | D7: =_xlfn.XLOOKUP(E7,Code!A:A,Code!B:B) | E7: 두산 | F7: 7 | G7: =B7&E7 | H7: =A7&B7&E7
A8: 46002 | B8: 삼성 | C8: 트루밸류 | D8: =_xlfn.XLOOKUP(E8,Code!A:A,Code!B:B) | E8: KT&G | F8: 5 | G8: =B8&E8 | H8: =A8&B8&E8
A9: 46002 | B9: 삼성 | C9: 트루밸류 | D9: =_xlfn.XLOOKUP(E9,Code!A:A,Code!B:B) | E9: 미래에셋증권 | F9: 5 | G9: =B9&E9 | H9: =A9&B9&E9
A10: 46002 | B10: 삼성 | C10: 트루밸류 | D10: =_xlfn.XLOOKUP(E10,Code!A:A,Code!B:B) | E10: 삼양식품 | F10: 3 | G10: =B10&E10 | H10: =A10&B10&E10
A11: 46002 | B11: 삼성 | C11: 트루밸류 | D11: =_xlfn.XLOOKUP(E11,Code!A:A,Code!B:B) | E11: CJ | F11: 3 | G11: =B11&E11 | H11: =A11&B11&E11
A12: 46002 | B12: 삼성 | C12: 트루밸류 | D12: =_xlfn.XLOOKUP(E12,Code!A:A,Code!B:B) | E12: OCI홀딩스 | F12: 3 | G12: =B12&E12 | H12: =A12&B12&E12
A13: 46002 | B13: 삼성 | C13: 트루밸류 | D13: =_xlfn.XLOOKUP(E13,Code!A:A,Code!B:B) | E13: 엔씨소프트 | F13: 0 | G13: =B13&E13 | H13: =A13&B13&E13
... A37: 46002 | B37: DB | C37: 자문형 랩 | D37: =_xlfn.XLOOKUP(E37,Code!A:A,Code!B:B) | E37: 엔씨소프트 | F37: 0 | G37: =B37&E37 | H37: =A37&B37&E37
A38: 46029 | B38: 삼성 | C38: 트루밸류 | D38: =_xlfn.XLOOKUP(E38,Code!A:A,Code!B:B) | E38: 삼성전자 | F38: 30 | G38: =B38&E38 | H38: =A38&B38&E38 | I38: {=_xlfn.XLOOKUP(G38,$G$2:G37,$H$2:H37,0,0,-1)} | J38: {=_xlfn.XLOOKUP(I38,$H$2:H37,$F$2:F37,0,0,-1)} | K38: =F38-J38 | L38: {=_xlfn.IFS(K38<0,"매도",K38>0,"매수",K38=0,"")}
A39: 46029 | B39: 삼성 | C39: 트루밸류 | D39: =_xlfn.XLOOKUP(E39,Code!A:A,Code!B:B) | E39: SK하이닉스 | F39: 15 | G39: =B39&E39 | H39: =A39&B39&E39 | I39: {=_xlfn.XLOOKUP(G39,$G$2:G38,$H$2:H38,0,0,-1)} | J39: {=_xlfn.XLOOKUP(I39,$H$2:H38,$F$2:F38,0,0,-1)} | K39: =F39-J39 | L39: {=_xlfn.IFS(K39<0,"매도",K39>0,"매수",K39=0,"")}
A40: 46029 | B40: 삼성 | C40: 트루밸류 | D40: =_xlfn.XLOOKUP(E40,Code!A:A,Code!B:B) | E40: 하이브 | F40: 5 | G40: =B40&E40 | H40: =A40&B40&E40 | I40: {=_xlfn.XLOOKUP(G40,$G$2:G39,$H$2:H39,0,0,-1)} | J40: {=_xlfn.XLOOKUP(I40,$H$2:H39,$F$2:F39,0,0,-1)} | K40: =F40-J40 | L40: {=_xlfn.IFS(K40<0,"매도",K40>0,"매수",K40=0,"")} | M40: 주가 단기 급등, 4분기 실적 우려로 비중 수익 실현
A41: 46029 | B41: 삼성 | C41: 트루밸류 | D41: =_xlfn.XLOOKUP(E41,Code!A:A,Code!B:B) | E41: 두산에너빌리티 | F41: 10 | G41: =B41&E41 | H41: =A41&B41&E41 | I41: {=_xlfn.XLOOKUP(G41,$G$2:G40,$H$2:H40,0,0,-1)} | J41: {=_xlfn.XLOOKUP(I41,$H$2:H40,$F$2:F40,0,0,-1)} | K41: =F41-J41 | L41: {=_xlfn.IFS(K41<0,"매도",K41>0,"매수",K41=0,"")}
A42: 46029 | B42: 삼성 | C42: 트루밸류 | D42: =_xlfn.XLOOKUP(E42,Code!A:A,Code!B:B) | E42: 알테오젠 | F42: 7 | G42: =B42&E42 | H42: =A42&B42&E42 | I42: {=_xlfn.XLOOKUP(G42,$G$2:G41,$H$2:H41,0,0,-1)} | J42: {=_xlfn.XLOOKUP(I42,$H$2:H41,$F$2:F41,0,0,-1)} | K42: =F42-J42 | L42: {=_xlfn.IFS(K42<0,"매도",K42>0,"매수",K42=0,"")}
A43: 46029 | B43: 삼성 | C43: 트루밸류 | D43: =_xlfn.XLOOKUP(E43,Code!A:A,Code!B:B) | E43: 두산 | F43: 7 | G43: =B43&E43 | H43: =A43&B43&E43 | I43: {=_xlfn.XLOOKUP(G43,$G$2:G42,$H$2:H42,0,0,-1)} | J43: {=_xlfn.XLOOKUP(I43,$H$2:H42,$F$2:F42,0,0,-1)} | K43: =F43-J43 | L43: {=_xlfn.IFS(K43<0,"매도",K43>0,"매수",K43=0,"")}
A44: 46029 | B44: 삼성 | C44: 트루밸류 | D44: =_xlfn.XLOOKUP(E44,Code!A:A,Code!B:B) | E44: KT&G | F44: 5 | G44: =B44&E44 | H44: =A44&B44&E44 | I44: {=_xlfn.XLOOKUP(G44,$G$2:G43,$H$2:H43,0,0,-1)} | J44: {=_xlfn.XLOOKUP(I44,$H$2:H43,$F$2:F43,0,0,-1)} | K44: =F44-J44 | L44: {=_xlfn.IFS(K44<0,"매도",K44>0,"매수",K44=0,"")}
A45: 46029 | B45: 삼성 | C45: 트루밸류 | D45: =_xlfn.XLOOKUP(E45,Code!A:A,Code!B:B) | E45: 미래에셋증권 | F45: 5 | G45: =B45&E45 | H45: =A45&B45&E45 | I45: {=_xlfn.XLOOKUP(G45,$G$2:G44,$H$2:H44,0,0,-1)} | J45: {=_xlfn.XLOOKUP(I45,$H$2:H44,$F$2:F44,0,0,-1)} | K45: =F45-J45 | L45: {=_xlfn.IFS(K45<0,"매도",K45>0,"매수",K45=0,"")}
A46: 46029 | B46: 삼성 | C46: 트루밸류 | D46: =_xlfn.XLOOKUP(E46,Code!A:A,Code!B:B) | E46: 삼양식품 | F46: 3 | G46: =B46&E46 | H46: =A46&B46&E46 | I46: {=_xlfn.XLOOKUP(G46,$G$2:G45,$H$2:H45,0,0,-1)} | J46: {=_xlfn.XLOOKUP(I46,$H$2:H45,$F$2:F45,0,0,-1)} | K46: =F46-J46 | L46: {=_xlfn.IFS(K46<0,"매도",K46>0,"매수",K46=0,"")}
A47: 46029 | B47: 삼성 | C47: 트루밸류 | D47: =_xlfn.XLOOKUP(E47,Code!A:A,Code!B:B) | E47: CJ | F47: 3 | G47: =B47&E47 | H47: =A47&B47&E47 | I47: {=_xlfn.XLOOKUP(G47,$G$2:G46,$H$2:H46,0,0,-1)} | J47: {=_xlfn.XLOOKUP(I47,$H$2:H46,$F$2:F46,0,0,-1)} | K47: =F47-J47 | L47: {=_xlfn.IFS(K47<0,"매도",K47>0,"매수",K47=0,"")}
A48: 46029 | B48: 삼성 | C48: 트루밸류 | D48: =_xlfn.XLOOKUP(E48,Code!A:A,Code!B:B) | E48: OCI홀딩스 | F48: 5 | G48: =B48&E48 | H48: =A48&B48&E48 | I48: {=_xlfn.XLOOKUP(G48,$G$2:G47,$H$2:H47,0,0,-1)} | J48: {=_xlfn.XLOOKUP(I48,$H$2:H47,$F$2:F47,0,0,-1)} | K48: =F48-J48 | L48: {=_xlfn.IFS(K48<0,"매도",K48>0,"매수",K48=0,"")} | M48: 4분기 실적 턴어라운드 기대 유효, 에너지에 대한 관심 증대
A49: 46029 | B49: 삼성 | C49: 트루밸류 | D49: =_xlfn.XLOOKUP(E49,Code!A:A,Code!B:B) | E49: 에이비엘바이오 | F49: 3 | G49: =B49&E49 | H49: =A49&B49&E49 | I49: {=_xlfn.XLOOKUP(G49,$G$2:G48,$H$2:H48,0,0,-1)} | J49: {=_xlfn.XLOOKUP(I49,$H$2:H48,$F$2:F48,0,0,-1)} | K49: =F49-J49 | L49: {=_xlfn.IFS(K49<0,"매도",K49>0,"매수",K49=0,"")} | M49: 블록딜 나온다는 논란에 대해 회사에서 사실 아님을 공식적으로 언급, 올해도 추가 딜 기대
A50: 46029 | B50: NH | C50: Value ESG | D50: =_xlfn.XLOOKUP(E50,Code!A:A,Code!B:B) | E50: 삼성전자 | F50: 30 | G50: =B50&E50 | H50: =A50&B50&E50 | I50: {=_xlfn.XLOOKUP(G50,$G$2:G49,$H$2:H49,0,0,-1)} | J50: {=_xlfn.XLOOKUP(I50,$H$2:H49,$F$2:F49,0,0,-1)} | K50: =F50-J50 | L50: {=_xlfn.IFS(K50<0,"매도",K50>0,"매수",K50=0,"")}
A51: 46029 | B51: NH | C51: Value ESG | D51: =_xlfn.XLOOKUP(E51,Code!A:A,Code!B:B) | E51: SK하이닉스 | F51: 15 | G51: =B51&E51 | H51: =A51&B51&E51 | I51: {=_xlfn.XLOOKUP(G51,$G$2:G50,$H$2:H50,0,0,-1)} | J51: {=_xlfn.XLOOKUP(I51,$H$2:H50,$F$2:F50,0,0,-1)} | K51: =F51-J51 | L51: {=_xlfn.IFS(K51<0,"매도",K51>0,"매수",K51=0,"")}
A52: 46029 | B52: NH | C52: Value ESG | D52: =_xlfn.XLOOKUP(E52,Code!A:A,Code!B:B) | E52: 하이브 | F52: 5 | G52: =B52&E52 | H52: =A52&B52&E52 | I52: {=_xlfn.XLOOKUP(G52,$G$2:G51,$H$2:H51,0,0,-1)} | J52: {=_xlfn.XLOOKUP(I52,$H$2:H51,$F$2:F51,0,0,-1)} | K52: =F52-J52 | L52: {=_xlfn.IFS(K52<0,"매도",K52>0,"매수",K52=0,"")} | M52: 4분기 실적 턴어라운드 기대 유효, 에너지에 대한 관심 증대
A53: 46029 | B53: NH | C53: Value ESG | D53: =_xlfn.XLOOKUP(E53,Code!A:A,Code!B:B) | E53: 두산에너빌리티 | F53: 10 | G53: =B53&E53 | H53: =A53&B53&E53 | I53: {=_xlfn.XLOOKUP(G53,$G$2:G52,$H$2:H52,0,0,-1)} | J53: {=_xlfn.XLOOKUP(I53,$H$2:H52,$F$2:F52,0,0,-1)} | K53: =F53-J53 | L53: {=_xlfn.IFS(K53<0,"매도",K53>0,"매수",K53=0,"")}
A54: 46029 | B54: NH | C54: Value ESG | D54: =_xlfn.XLOOKUP(E54,Code!A:A,Code!B:B) | E54: 알테오젠 | F54: 7 | G54: =B54&E54 | H54: =A54&B54&E54 | I54: {=_xlfn.XLOOKUP(G54,$G$2:G53,$H$2:H53,0,0,-1)} | J54: {=_xlfn.XLOOKUP(I54,$H$2:H53,$F$2:F53,0,0,-1)} | K54: =F54-J54 | L54: {=_xlfn.IFS(K54<0,"매도",K54>0,"매수",K54=0,"")}
A55: 46029 | B55: NH | C55: Value ESG | D55: =_xlfn.XLOOKUP(E55,Code!A:A,Code!B:B) | E55: 두산 | F55: 7 | G55: =B55&E55 | H55: =A55&B55&E55 | I55: {=_xlfn.XLOOKUP(G55,$G$2:G54,$H$2:H54,0,0,-1)} | J55: {=_xlfn.XLOOKUP(I55,$H$2:H54,$F$2:F54,0,0,-1)} | K55: =F55-J55 | L55: {=_xlfn.IFS(K55<0,"매도",K55>0,"매수",K55=0,"")}
A56: 46029 | B56: NH | C56: Value ESG | D56: =_xlfn.XLOOKUP(E56,Code!A:A,Code!B:B) | E56: KT&G | F56: 5 | G56: =B56&E56 | H56: =A56&B56&E56 | I56: {=_xlfn.XLOOKUP(G56,$G$2:G55,$H$2:H55,0,0,-1)} | J56: {=_xlfn.XLOOKUP(I56,$H$2:H55,$F$2:F55,0,0,-1)} | K56: =F56-J56 | L56: {=_xlfn.IFS(K56<0,"매도",K56>0,"매수",K56=0,"")}
A57: 46029 | B57: NH | C57: Value ESG | D57: =_xlfn.XLOOKUP(E57,Code!A:A,Code!B:B) | E57: 미래에셋증권 | F57: 5 | G57: =B57&E57 | H57: =A57&B57&E57 | I57: {=_xlfn.XLOOKUP(G57,$G$2:G56,$H$2:H56,0,0,-1)} | J57: {=_xlfn.XLOOKUP(I57,$H$2:H56,$F$2:F56,0,0,-1)} | K57: =F57-J57 | L57: {=_xlfn.IFS(K57<0,"매도",K57>0,"매수",K57=0,"")}
A58: 46029 | B58: NH | C58: Value ESG | D58: =_xlfn.XLOOKUP(E58,Code!A:A,Code!B:B) | E58: 삼양식품 | F58: 3 | G58: =B58&E58 | H58: =A58&B58&E58 | I58: {=_xlfn.XLOOKUP(G58,$G$2:G57,$H$2:H57,0,0,-1)} | J58: {=_xlfn.XLOOKUP(I58,$H$2:H57,$F$2:F57,0,0,-1)} | K58: =F58-J58 | L58: {=_xlfn.IFS(K58<0,"매도",K58>0,"매수",K58=0,"")}
A59: 46029 | B59: NH | C59: Value ESG | D59: =_xlfn.XLOOKUP(E59,Code!A:A,Code!B:B) | E59: CJ | F59: 3 | G59: =B59&E59 | H59: =A59&B59&E59 | I59: {=_xlfn.XLOOKUP(G59,$G$2:G58,$H$2:H58,0,0,-1)} | J59: {=_xlfn.XLOOKUP(I59,$H$2:H58,$F$2:F58,0,0,-1)} | K59: =F59-J59 | L59: {=_xlfn.IFS(K59<0,"매도",K59>0,"매수",K59=0,"")}
A60: 46029 | B60: NH | C60: Value ESG | D60: =_xlfn.XLOOKUP(E60,Code!A:A,Code!B:B) | E60: OCI홀딩스 | F60: 5 | G60: =B60&E60 | H60: =A60&B60&E60 | I60: {=_xlfn.XLOOKUP(G60,$G$2:G59,$H$2:H59,0,0,-1)} | J60: {=_xlfn.XLOOKUP(I60,$H$2:H59,$F$2:F59,0,0,-1)} | K60: =F60-J60 | L60: {=_xlfn.IFS(K60<0,"매도",K60>0,"매수",K60=0,"")} | M60: 4분기 실적 턴어라운드 기대 유효, 에너지에 대한 관심 증대
A61: 46029 | B61: NH | C61: Value ESG | D61: =_xlfn.XLOOKUP(E61,Code!A:A,Code!B:B) | E61: 에이비엘바이오 | F61: 3 | G61: =B61&E61 | H61: =A61&B61&E61 | I61: {=_xlfn.XLOOKUP(G61,$G$2:G60,$H$2:H60,0,0,-1)} | J61: {=_xlfn.XLOOKUP(I61,$H$2:H60,$F$2:F60,0,0,-1)} | K61: =F61-J61 | L61: {=_xlfn.IFS(K61<0,"매도",K61>0,"매수",K61=0,"")} | M61: 블록딜 나온다는 논란에 대해 회사에서 사실 아님을 공식적으로 언급, 올해도 추가 딜 기대
A62: 46029 | B62: DB | C62: 자문형 랩 | D62: =_xlfn.XLOOKUP(E62,Code!A:A,Code!B:B) | E62: 삼성전자 | F62: 30 | G62: =B62&E62 | H62: =A62&B62&E62 | I62: {=_xlfn.XLOOKUP(G62,$G$2:G61,$H$2:H61,0,0,-1)} | J62: {=_xlfn.XLOOKUP(I62,$H$2:H61,$F$2:F61,0,0,-1)} | K62: =F62-J62 | L62: {=_xlfn.IFS(K62<0,"매도",K62>0,"매수",K62=0,"")}
A63: 46029 | B63: DB | C63: 자문형 랩 | D63: =_xlfn.XLOOKUP(E63,Code!A:A,Code!B:B) | E63: SK하이닉스 | F63: 15 | G63: =B63&E63 | H63: =A63&B63&E63 | I63: {=_xlfn.XLOOKUP(G63,$G$2:G62,$H$2:H62,0,0,-1)} | J63: {=_xlfn.XLOOKUP(I63,$H$2:H62,$F$2:F62,0,0,-1)} | K63: =F63-J63 | L63: {=_xlfn.IFS(K63<0,"매도",K63>0,"매수",K63=0,"")}
...

Sheet 기준가
A1: Date | B1: 트루밸류 | C1: Value ESG | D1: 자문형 랩 | E1: KOSPI | F1: KOSDAQ
A2: 46021 | B2: 2021.31 | C2: 1980.49 | D2: 1518.52 | E2: 4214.17 | F2: 925.47
A3: 46024 | B3: 2089.49 | C3: 2047.3 | D3: 1569.74 | E3: 4309.63 | F3: 945.57
A4: 46027 | B4: 2178.4 | C4: 2134.41 | D4: 1636.54 | E4: 4457.52 | F4: 957.5
A5: 46028 | B5: 2217.75 | C5: 2172.96 | D5: 1666.09 | E5: 4525.48 | F5: 955.97

Sheet Code
A1: 종목명 | B1: 종목코드 | C1: 시장구분
A2: 삼성전자 | B2: 005930 | C2: KOSPI
A3: SK하이닉스 | B3: 000660 | C3: KOSPI
A4: LG에너지솔루션 | B4: 373220 | C4: KOSPI
A5: 삼성바이오로직스 | B5: 207940 | C5: KOSPI
A6: 삼성전자우 | B6: 005935 | C6: KOSPI
A7: 현대차 | B7: 005380 | C7: KOSPI
A8: 셀트리온 | B8: 068270 | C8: KOSPI
A9: 기아 | B9: 000270 | C9: KOSPI
A10: POSCO홀딩스 | B10: 005490 | C10: KOSPI
A11: NAVER | B11: 035420 | C11: KOSPI
A12: LG화학 | B12: 051910 | C12: KOSPI
... A2786: 베른 | B2786: 322190 | C2786: KONEX
A2787: 우진엔텍 | B2787: 457550 | C2787: KOSDAQ
A2788: 폰드그룹 | B2788: 472850 | C2788: KOSDAQ
A2789: HD현대마린솔루션 | B2789: 443060 | C2789: KOSPI
A2790: 에이피알 | B2790: 278470 | C2790: KOSPI
A2791: 산일전기 | B2791: 062040 | C2791: KOSPI
A2792: 한화인더스트리얼솔루션즈 | B2792: 489790 | C2792: KOSPI
A2793: 에이치브이엠 | B2793: 295310 | C2793: KOSDAQ
A2794: 노머스 | B2794: 473980 | C2794: KOSDAQ
A2795: 시프트업 | B2795: 462870 | C2795: KOSPI
A2796: 아이티센글로벌 | B2796: 124500 | C2796: KOSDAQ
